<?xml version="1.0"?>  <!-- Declaration of xml tag   -->

 <!--Declaration of xacro file format-->
<robot xmlns:xacro="https://www.ros.org/wiki/xacro">  
 

<!--Delcaration of colors which has been used for the links-->
    <material name="white">
        <color rgba="1.0 1.0 1.0 1.0"/>
    </material>
    <material name="black">
        <color rgba="0.0 0.0 0.0 1.0"/>
    </material>
    <material name="red">
        <color rgba="1.0 0.0 0.0 1.0"/>
    </material>
    <material name="blue">
        <color rgba="0.0 0.0 1.0 1.0"/>
    </material>
    

    <link
    name="base_link">
  </link>
  <joint name="base_footprint_joint" type="fixed">
        <origin xyz="0.0 0.0 0.0" rpy="0.0 0.0 0.0"/>
        <parent link="base_link"/>
        <child link="base_footprint"/>
        <axis xyz="0.0 0.0 0.0"/>
    </joint>
    <link name="base_footprint">
    </link>
    
  <link name="left_wheel">
    <inertial>
      <origin
        xyz="-8.83488102121355E-10 5.46856449012978E-11 -0.00153990809638952"
        rpy="0 0 0" />
      <mass
        value="0.0351743518689195" />
      <inertia
        ixx="1.52365643010477E-05"
        ixy="3.0840857389948E-10"
        ixz="-9.97409077694242E-14"
        iyy="1.5237343017232E-05"
        iyz="-6.11272444343794E-14"
        izz="2.57855724460667E-05" />
    </inertial>
    <visual>
      <origin xyz="0 0 0" rpy="0 0 0" />
      <geometry>
        <mesh
          filename="package://medox_robot/meshes/left_wheel.STL" />
      </geometry>
      <material name="blue" />
    </visual>
    <collision>
      <origin xyz="0 0 0" rpy="0 0 0" />
      <geometry>
        <mesh
          filename="package://medox_robot/meshes/left_wheel.STL" />
      </geometry>
    </collision>
  </link>
  <joint  name="left_wheel_joint" type="continuous">
    <origin xyz="0 0.138 -0.0210000000000002" rpy="-1.5707963267949 0 0" />
    <parent link="base_link" />
    <child  link="left_wheel" />
    <axis xyz="0 0 1" />
  </joint>
  <link name="right_wheel">
    <inertial>
      <origin xyz="7.70630951413276E-10 -3.32503330424672E-10 -0.00153990805361556" rpy="0 0 0" />
      <mass value="0.0351743514548104" />
      <inertia
        ixx="1.52365640491052E-05"
        ixy="3.08509166722093E-10"
        ixz="8.38334222583704E-14"
        iyy="1.52373429696304E-05"
        iyz="2.27587680472107E-14"
        izz="2.57855721584521E-05" />
    </inertial>
    <visual>
      <origin xyz="0 0 0" rpy="0 0 0" />
      <geometry>
        <mesh
          filename="package://medox_robot/meshes/right_wheel.STL" />
      </geometry>
      <material name="blue" />
    </visual>  
    <collision>
      <origin xyz="0 0 0" rpy="0 0 0" />
      <geometry>
        <mesh
          filename="package://medox_robot/meshes/right_wheel.STL" />
      </geometry>
    </collision>
  </link>
  <joint
    name="right_wheel_joint"
    type="continuous">
    <origin xyz="0 -0.138 -0.0210000000000002"  rpy="-1.5707963267949 0 0" />
    <parent link="base_link" />
    <child  link="right_wheel" />
    <axis xyz="0 0 1" />
  </joint>
  <link name="castor_wheel_f">
    <inertial>
      <origin xyz="0 -5.55111512312578E-17 -0.0161355568158763" rpy="0 0 0" />
      <mass value="0.00448472842670636" />
      <inertia
        ixx="7.32465415243615E-07"
        ixy="-1.23592415742786E-22"
        ixz="3.531673838546E-22"
        iyy="5.9050285314133E-07"
        iyz="-3.23587887691373E-21"
        izz="5.39736643368085E-07" />
    </inertial>
    <visual>
      <origin xyz="0 0 0" rpy="0 0 0" />
      <geometry>
        <mesh
          filename="package://medox_robot/meshes/castor_wheel_f.STL" />
      </geometry>
      <material name="black" />
    </visual>
    <collision>
      <origin xyz="0 0 0" rpy="0 0 0" />
      <geometry>
        <mesh
          filename="package://medox_robot/meshes/castor_wheel_f.STL" />
      </geometry>
    </collision>
  </link>
  <joint name="castor_wheel_f_joint" type="fixed">
    <origin xyz="0.1875 0 0" rpy="0 0 0" />
    <parent link="base_link" />
    <child link="castor_wheel_f" />
    <axis xyz="0 0 1" />
  </joint>
  <link
    name="castor_wheel_f1">
    <inertial>
      <origin
        xyz="0 0 -1.38777878078145E-17"
        rpy="0 0 0" />
      <mass
        value="0.0215237500041331" />
      <inertia
        ixx="2.68174134760054E-06"
        ixy="5.38159277687387E-39"
        ixz="1.07427957226757E-23"
        iyy="2.68174134760054E-06"
        iyz="3.20819031209118E-23"
        izz="3.97300328662299E-06" />
    </inertial>
    <visual>
      <origin xyz="0 0 0" rpy="0 0 0" />
      <geometry>
        <mesh
          filename="package://medox_robot/meshes/castor_wheel_f1.STL" />
      </geometry>
      <material name="white" />
    </visual>
    <collision>
      <origin xyz="0 0 0" rpy="0 0 0" />
      <geometry>
        <mesh
          filename="package://medox_robot/meshes/castor_wheel_f1.STL" />
      </geometry>
    </collision>
  </link>
  <joint name="castor_wheel_f1_jont" type="fixed">
    <origin xyz="0 0 -0.0356000000000001" rpy="-1.5707963267949 0 0" />
    <parent link="castor_wheel_f" />
    <child link="castor_wheel_f1" />
    <axis xyz="0 1 0" />
  </joint>
  <link name="castor_wheel_b">
    <inertial>
      <origin xyz="0 -5.55111512312578E-17 -0.0145355568158763" rpy="0 0 0" />
      <mass
        value="0.00448472842670636" />
      <inertia
        ixx="7.32465415243615E-07"
        ixy="-6.97731693449958E-23"
        ixz="4.00566546990044E-22"
        iyy="5.9050285314133E-07"
        iyz="-3.53808807516372E-21"
        izz="5.39736643368085E-07" />
    </inertial>
    <visual>
      <origin xyz="0 0 0" rpy="0 0 0" />
      <geometry>
        <mesh
          filename="package://medox_robot/meshes/castor_wheel_b.STL" />
      </geometry>
      <material name="black" />
    </visual>
    <collision>
      <origin xyz="0 0 0" rpy="0 0 0" />
      <geometry>
        <mesh
          filename="package://medox_robot/meshes/castor_wheel_b.STL" />
      </geometry>
    </collision>
  </link>
  <joint name="castor_wheel_b_joint" type="fixed">
    <origin xyz="-0.1875 0 0" rpy="0 0 0" />
    <parent link="base_link" />
    <child link="castor_wheel_b" />
    <axis xyz="0 0 1" />
  </joint>
  <link name="castor_wheel_b1">
    <inertial>
      <origin xyz="5.55111512312578E-17 2.77555756156289E-17 1.38777878078145E-17" rpy="0 0 0" />
      <mass
        value="0.0215237500041331" />
      <inertia
        ixx="2.68174134760053E-06"
        ixy="5.29823666801976E-39"
        ixz="1.20662847027604E-23"
        iyy="2.68174134760053E-06"
        iyz="3.20819031209118E-23"
        izz="3.97300328662299E-06" />
    </inertial>
    <visual>
      <origin xyz="0 0 0" rpy="0 0 0" />
      <geometry>
        <mesh
          filename="package://medox_robot/meshes/castor_wheel_b1.STL" />
      </geometry>
      <material name="white" />
    </visual>
    <collision>
      <origin xyz="0 0 0" rpy="0 0 0" />
      <geometry>
        <mesh
          filename="package://medox_robot/meshes/castor_wheel_b1.STL" />
      </geometry>
    </collision>
  </link>
  <joint name="castor_wheel_b1_joint" type="fixed">
    <origin xyz="0 0 -0.034" rpy="-1.5707963267949 0 0" />
    <parent link="castor_wheel_b" />
    <child link="castor_wheel_b1" />
    <axis xyz="0 1 0" />
  </joint>
  <link name="chassis">
    <inertial>
      <origin xyz="-2.74086309204336E-16 -1.38777878078145E-17 -0.0646619925057325" rpy="0 0 0" />
      <mass
        value="3.0292673007409" />
      <inertia
        ixx="0.02938363321042"
        ixy="-2.92144499331735E-10"
        ixz="5.82774801545193E-18"
        iyy="0.0614401847263212"
        iyz="-3.32884714211855E-19"
        izz="0.0891491492281097" />
    </inertial>
    <visual>
      <origin xyz="0 0 0" rpy="0 0 0" />
      <geometry>
        <mesh
          filename="package://medox_robot/meshes/chassis.STL" />
      </geometry>
      <material name="red" />
    </visual>
    <collision>
      <origin xyz="0 0 0" rpy="0 0 0" />
      <geometry>
        <mesh
          filename="package://medox_robot/meshes/chassis.STL" />
      </geometry>
    </collision>
  </link>
  <joint name="chassis_joint" type="fixed">
    <origin xyz="0 0 0.126" rpy="0 0 0" />
    <parent link="base_link" />
    <child link="chassis" />
    <axis xyz="0 0 0" />
  </joint>
  <link name="lidar_link">
    <inertial>
      <origin xyz="-0.00675749326271478 0.000361476187292389 -0.00738187226715975" rpy="0 0 0" />
      <mass
        value="1.33076913637071" />
      <inertia
        ixx="0.000615403089759156"
        ixy="1.2967746229346E-05"
        ixz="-0.000157994159952965"
        iyy="0.000960212186312159"
        iyz="9.39461790111298E-06"
        izz="0.00109815200027136" />
    </inertial>
    <visual>
      <origin xyz="0 0 0" rpy="0 0 0" />
      <geometry>
        <mesh
          filename="package://medox_robot/meshes/lidar_link.STL" />
      </geometry>
      <material name="black" />
    </visual>
    <collision>
      <origin xyz="0 0 0" rpy="0 0 0" />
      <geometry>
        <mesh
          filename="package://medox_robot/meshes/lidar_link.STL" />
      </geometry>
    </collision>
  </link>
  <joint name="lidar_joint" type="fixed">
    <origin xyz="0.0151 0.0024244 0.04265" rpy="0 0 0" />
    <parent link="chassis" />
    <child link="lidar_link" />
    <axis xyz="0 0 0" />
  </joint>
</robot>
     

